<?xml version="1.0"?>

<!-- * Author:  Paulo Rezeck * -->
<!-- * Email: rezeck@dcc.ufmg.br * -->

<robot xmlns:xacro="http://wiki.ros.org/xacro">

  <xacro:macro name="fenrir_arm" params="parent *origin">
    <!-- ****************************************************** -->
    <!-- *                                          Macros                                                       -->
    <!-- ****************************************************** -->
    <xacro:macro name="transmission_block" params="joint_name">
      <transmission name="tran1">
        <type>transmission_interface/SimpleTransmission</type>
        <joint name="${joint_name}">
          <hardwareInterface>hardware_interface/PositionJointInterface</hardwareInterface>
          <!--hardwareInterface>hardware_interface/VelocityJointInterface</hardwareInterface-->
          <!--hardwareInterface>hardware_interface/EffortJointInterface</hardwareInterface-->
        </joint>
        <actuator name="${joint_name}_motor">
          <hardwareInterface>hardware_interface/EffortJointInterface</hardwareInterface>
          <mechanicalReduction>1</mechanicalReduction>
        </actuator>
      </transmission>
    </xacro:macro>

    <!-- from mimic_joint_gazebo_tutorial by @mintar, refer: https://github.com/mintar/mimic_joint_gazebo_tutorial -->
    <xacro:macro name="mimic_joint_plugin_gazebo" params="name_prefix following_joint mimic_joint has_pid:=false multiplier:=1.0 offset:=0 sensitiveness:=0.0 max_effort:=1.0 robot_namespace:=''">
      <gazebo>
        <!-- old version -->
        <plugin name="${name_prefix}mimic_joint_plugin" filename="libroboticsgroup_upatras_gazebo_mimic_joint_plugin.so">
          <joint>${following_joint}</joint>
          <mimicJoint>${mimic_joint}</mimicJoint>
          <xacro:if value="${has_pid}">
            <!-- if set to true, PID parameters from "/gazebo_ros_control/pid_gains/${mimic_joint}" are loaded -->
            <hasPID />
          </xacro:if>
          <multiplier>${multiplier}</multiplier>
          <offset>${offset}</offset>
          <sensitiveness>${sensitiveness}</sensitiveness> <!-- if absolute difference between setpoint and process value is below this threshold, do nothing; 0.0 = disable [rad] -->
          <maxEffort>${max_effort}</maxEffort> <!-- only taken into account if has_pid:=true [Nm] -->
          <xacro:unless value="${robot_namespace == ''}">
            <robotNamespace>($robot_namespace)</robotNamespace>
          </xacro:unless>
        </plugin>
      </gazebo>
    </xacro:macro>


    <!-- ****************************************************** -->
    <!-- *                                          Links                                                           -->
    <!-- ****************************************************** -->
    <!-- LINKS: main serial links -->
    <!-- Base link #1 -->
    <link name="base_link">
      <visual>
        <origin xyz="0 0 0" rpy="0 0 0" />
        <geometry>
          <mesh filename="package://fenrir_description/meshes/visual/base_link.dae" scale="1.0 1.0 1.0" />
        </geometry>
      </visual>
      <collision>
        <origin xyz="0 0 0" rpy="0 0 0 " />
        <geometry>
          <mesh filename="package://fenrir_description/meshes/collision/base_link.stl" scale="0.01 0.01 0.01" />
        </geometry>
      </collision>
      <inertial>
        <origin xyz="0 0 0.041" rpy="0 0 0" />
        <mass value="0.450" />
        <inertia ixx="0.0011014" ixy="0.0000111" ixz="-0.0000032" iyy="0.0010823" iyz="0.000008" izz="0.0013862" />
      </inertial>
    </link>
    <gazebo reference="base_link">
      <gravity>1</gravity>
      <selfCollide>0</selfCollide>
      <kinematic>1</kinematic>
    </gazebo>

    <!-- Shoulder link #2 -->
    <link name="shoulder_link">
      <visual>
        <origin xyz="0 0 0" rpy="0 0 0" />
        <geometry>
          <mesh filename="package://fenrir_description/meshes/visual/shoulder.dae" scale="1.0 1.0 1.0" />
        </geometry>
      </visual>
      <collision>
        <origin xyz="0 0 0" rpy="0 0 0" />
        <geometry>
          <mesh filename="package://fenrir_description/meshes/collision/shoulder.stl" scale="1.0 1.0 1.0" />
        </geometry>
      </collision>
      <inertial>
        <origin xyz="0 0 0.05" rpy="0 0 0" />
        <mass value="0.550" />
        <inertia ixx="0.0013305" ixy="0.0" ixz="0.0000025" iyy="0.000682" iyz="0.0" izz="0.0011533" />
      </inertial>
    </link>
    <gazebo reference="shoulder_link">
      <gravity>1</gravity>
      <selfCollide>0</selfCollide>
      <kinematic>1</kinematic>
    </gazebo>

    <!-- Arm link #3 -->
    <link name="arm_link">
      <visual>
        <origin xyz="0 0 0.006" rpy="0 0 0" />
        <geometry>
          <mesh filename="package://fenrir_description/meshes/visual/arm.dae" scale="1.0 1.0 1.0" />
        </geometry>
      </visual>
      <collision>
        <origin xyz="0 0 0.006" rpy="0 0 0" />
        <geometry>
          <mesh filename="package://fenrir_description/meshes/collision/arm.stl" scale="1.0 1.0 1.0" />
        </geometry>
      </collision>
      <inertial>
        <origin xyz="0 0 0.081" rpy="0 0 0" />
        <mass value="0.350" />
        <inertia ixx="0.0016465460938" ixy="0.0000000673555" ixz="0.0000034090355" iyy="0.0016018608398" iyz="0.0002222412354" izz="0.0001852667358" />
      </inertial>
    </link>
    <gazebo reference="arm_link">
      <gravity>1</gravity>
      <selfCollide>0</selfCollide>
      <kinematic>1</kinematic>
    </gazebo>

    <!-- Forearm link #4 -->
    <link name="forearm_link">
      <visual>
        <origin xyz="0 0 0" rpy="0 0 0" />
        <geometry>
          <mesh filename="package://fenrir_description/meshes/visual/forearm.dae" scale="1.0 1.0 1.0" />
        </geometry>
      </visual>
      <collision>
        <origin xyz="0 0 0" rpy="0 0 0" />
        <geometry>
          <mesh filename="package://fenrir_description/meshes/collision/forearm.stl" scale="1.0 1.0 1.0" />
        </geometry>
      </collision>
      <inertial>
        <origin xyz="0 0 0.08" rpy="0 0 0" />
        <mass value="0.350" />
        <inertia ixx="0.0005336" ixy="0.0000008" ixz="0.0000025" iyy="0.0005186" iyz="-0.0000849" izz="0.0000674" />
      </inertial>
    </link>
    <gazebo reference="forearm_link">
      <gravity>1</gravity>
      <selfCollide>0</selfCollide>
      <kinematic>1</kinematic>
    </gazebo>

    <!-- Gripper base link #5 -->
    <link name="gripper_base_link">
      <visual>
        <origin xyz="0 0 0" rpy="0 0 0" />
        <geometry>
          <mesh filename="package://fenrir_description/meshes/visual/wrist.dae" scale="1.0 1.0 1.0" />
        </geometry>
      </visual>
      <collision>
        <origin xyz="0 0 0" rpy="0 0 0" />
        <geometry>
          <mesh filename="package://fenrir_description/meshes/collision/wrist.stl" scale="1.0 1.0 1.0" />
        </geometry>
      </collision>
      <inertial>
        <origin xyz="0 0 0.02" rpy="0 0 0" />
        <mass value="0.155" />
        <inertia ixx="0.0000432" ixy="-0.0000008" ixz="0.0000011" iyy="0.0000346" iyz="-0.0000001" izz="0.0000354" />
      </inertial>
    </link>
    <gazebo reference="gripper_base_link">
      <gravity>1</gravity>
      <selfCollide>0</selfCollide>
      <kinematic>1</kinematic>
    </gazebo>

    <!-- Driving gear link #6 -->
    <link name="driving_gear_link">
      <visual>
        <origin xyz="0 0 0" rpy="0 ${pi/2} 0" />
        <geometry>
          <mesh filename="package://fenrir_description/meshes/visual/driving_gear.dae" scale="1 1 1" />
        </geometry>
      </visual>
      <collision>
        <origin xyz="0 0 0" rpy="0 ${pi/2} 0" />
        <geometry>
          <mesh filename="package://fenrir_description/meshes/collision/driving_gear.stl" scale="1 1 1" />
        </geometry>
      </collision>
      <inertial>
        <mass value="0.030" />
        <inertia ixx="0.0000033" ixy="0" ixz="0" iyy="0.0000005" iyz="-0.0000002" izz="0.0000035" />
      </inertial>
    </link>
    <gazebo reference="driving_gear_link">
      <gravity>1</gravity>
      <selfCollide>0</selfCollide>
      <kinematic>1</kinematic>
    </gazebo>


    <link name="slave_gear_link">
      <visual>
        <origin xyz="0 0 0" rpy="0 ${-pi/2} 0" />
        <geometry>
          <mesh filename="package://fenrir_description/meshes/visual/slave_gear.dae" scale="1.0 1.0 1.0" />
        </geometry>
      </visual>
      <collision>
        <origin xyz="0 0 0" rpy="0 ${-pi/2} 0" />
        <geometry>
          <mesh filename="package://fenrir_description/meshes/collision/slave_gear.stl" scale="1.0 1.0 1.0" />
        </geometry>
      </collision>
      <inertial>
        <mass value="0.030" />
        <inertia ixx="0.000003" ixy="0.0" ixz="0.0" iyy="0.0000003" iyz="0.0" izz="0.0000032" />
      </inertial>
    </link>
    <gazebo reference="slave_gear_link">
      <gravity>1</gravity>
      <selfCollide>0</selfCollide>
      <kinematic>1</kinematic>
    </gazebo>


    <link name="rod_link">
      <visual>
        <origin xyz="-0.0035 0 0" rpy="${pi/2} 0 ${pi/2}" />
        <geometry>
          <mesh filename="package://fenrir_description/meshes/visual/secondaryRod.dae" scale="1.0 1.0 1.0" />
        </geometry>
      </visual>
      <collision>
        <origin xyz="-0.0035 0 0" rpy="${pi/2} 0 ${pi/2}" />
        <geometry>
          <mesh filename="package://fenrir_description/meshes/collision/secondaryRod.stl" scale="1.0 1.0 1.0" />
        </geometry>
      </collision>
      <inertial>
        <mass value="0.010" />
        <inertia ixx="0.0" ixy="0.0" ixz="0.0" iyy="0.0000008" iyz="0.0" izz="0.0000008" />
      </inertial>
    </link>
    <gazebo reference="rod_link">
      <gravity>1</gravity>
      <selfCollide>0</selfCollide>
      <kinematic>1</kinematic>
    </gazebo>


    <link name="rod_slave_link">
      <visual>
        <origin xyz="0.0035 0 0" rpy="${pi/2} 0 ${-pi/2}" />
        <geometry>
          <mesh filename="package://fenrir_description/meshes/visual/secondaryRod.dae" scale="1.0 1.0 1.0" />
        </geometry>
      </visual>
      <collision>
        <origin xyz="0.0035 0 0" rpy="${pi/2} 0 ${-pi/2}" />
        <geometry>
          <mesh filename="package://fenrir_description/meshes/collision/secondaryRod.stl" scale="1.0 1.0 1.0" />
        </geometry>
      </collision>
      <inertial>
        <mass value="0.010" />
        <inertia ixx="0.0" ixy="0.0" ixz="0.0" iyy="0.0000008" iyz="0.0" izz="0.0000008" />
      </inertial>
    </link>
    <gazebo reference="rod_slave_link">
      <gravity>1</gravity>
      <selfCollide>0</selfCollide>
      <kinematic>1</kinematic>
    </gazebo>


    <link name="gripper_tip_link">
      <visual>
        <origin xyz="0.0092 0 0" rpy="0 ${pi/2} 0" />
        <geometry>
          <mesh filename="package://fenrir_description/meshes/visual/gripperTip.dae" scale="1.0 1.0 1.0" />
        </geometry>
      </visual>
      <collision>
        <origin xyz="0.0092 0 0" rpy="0 ${pi/2} 0" />
        <geometry>
          <mesh filename="package://fenrir_description/meshes/collision/gripperTip.stl" scale="1.0 1.0 1.0" />
        </geometry>
      </collision>
      <inertial>
        <mass value="0.020" />
        <inertia ixx="0.0000008" ixy="-0.0000001" ixz="0.0" iyy="0.0000055" iyz="0.0" izz="0.0000054" />
      </inertial>
    </link>
    <gazebo reference="gripper_tip_link">
      <gravity>1</gravity>
      <selfCollide>0</selfCollide>
      <kinematic>1</kinematic>
    </gazebo>


    <link name="tip_slave_link">
      <visual>
        <origin xyz="0.0092 0 0" rpy="${pi} ${pi/2} 0" />
        <geometry>
          <mesh filename="package://fenrir_description/meshes/visual/gripperTip.dae" scale="1.0 1.0 1.0" />
        </geometry>
      </visual>
      <collision>
        <origin xyz="0.0092 0 0" rpy="${pi} ${pi/2} 0" />
        <geometry>
          <mesh filename="package://fenrir_description/meshes/collision/gripperTip.stl" scale="1.0 1.0 1.0" />
        </geometry>
      </collision>
      <inertial>
        <mass value="0.020" />
        <inertia ixx="0.0000008" ixy="-0.0000001" ixz="0.0" iyy="0.0000055" iyz="0.0" izz="0.0000054" />
      </inertial>
    </link>
    <gazebo reference="tip_slave_link">
      <gravity>1</gravity>
      <selfCollide>0</selfCollide>
      <kinematic>1</kinematic>
    </gazebo>


    <!-- ****** JOINT DEFINITIONS ****** -->
    <joint name="base_fixed_joint" type="fixed">
      <xacro:insert_block name="origin" />
      <parent link="${parent}" />
      <child link="base_link" />
    </joint>

    <joint name="base_joint" type="revolute">
      <origin xyz="0 0 0.082" rpy="0 0 0" />
      <parent link="base_link" />
      <child link="shoulder_link" />
      <axis xyz="0 0 1" />
      <limit lower="-2.967" upper="2.967" effort="300" velocity="4.01" />
      <dynamics damping="50" friction="1" />
    </joint>
    <xacro:transmission_block joint_name="base_joint" />
    <gazebo reference="base_joint">
      <provideFeedback>0</provideFeedback>
    </gazebo>


    <joint name="shoulder_joint" type="revolute">
      <origin xyz="0 0 0.082" rpy="0 0 0" />
      <parent link="shoulder_link" />
      <child link="arm_link" />
      <axis xyz="0 -1 0" />
      <limit lower="-2.2" upper="2.2" effort="300" velocity="4.93" />
      <dynamics damping="50" friction="1" />
    </joint>
    <xacro:transmission_block joint_name="shoulder_joint" />
    <gazebo reference="shoulder_joint">
      <provideFeedback>0</provideFeedback>
    </gazebo>


    <joint name="elbow_joint" type="revolute">
      <origin xyz="0 0.001 0.195" rpy="0 0 0" />
      <parent link="arm_link" />
      <child link="forearm_link" />
      <axis xyz="0 -1 0" />
      <limit lower="-2.4" upper="2.4" effort="300" velocity="7.01" />
      <dynamics damping="50" friction="1" />
    </joint>
    <xacro:transmission_block joint_name="elbow_joint" />
    <gazebo reference="elbow_joint">
      <provideFeedback>0</provideFeedback>
    </gazebo>

    <joint name="wrist_joint" type="revolute">
      <origin xyz="0 0 0.19" rpy="0 0 -${pi}" />
      <parent link="forearm_link" />
      <child link="gripper_base_link" />
      <axis xyz="0 0 1" />
      <limit lower="-${pi/2}" upper="${pi/2}" effort="100" velocity="4.50" />
      <dynamics damping="50" friction="1" />
    </joint>
    <xacro:transmission_block joint_name="wrist_joint" />
    <gazebo reference="wrist_joint">
      <provideFeedback>0</provideFeedback>
    </gazebo>

    <joint name="gripper_joint" type="revolute">
      <origin xyz="-0.011 -0.014 0.0262" rpy="${pi-0.35} 0 0" />
      <parent link="gripper_base_link" />
      <child link="driving_gear_link" />
      <axis xyz="1 0 0" />
      <limit lower="-0.83" upper="0" effort="100" velocity="4.50" />
      <dynamics damping="50" friction="1" />
    </joint>
    <xacro:transmission_block joint_name="gripper_joint" />
    <gazebo reference="gripper_joint">
      <provideFeedback>0</provideFeedback>
    </gazebo>

    <joint name="gripper_slave_joint" type="revolute">
      <origin xyz="0.005 0.0137 0.0262" rpy="${pi+0.35} 0 0" />
      <parent link="gripper_base_link" />
      <child link="slave_gear_link" />
      <axis xyz="1 0 0" />
      <limit lower="-3.31" upper="3.31" effort="100" velocity="4.50" />
      <dynamics damping="50" friction="1" />
      <mimic joint="gripper_joint" multiplier="-1" offset="0" />
    </joint>
    <!-- mimic_joint_plugin has to be installed: -->
    <xacro:mimic_joint_plugin_gazebo name_prefix="gripper_slave_joint" following_joint="gripper_joint" mimic_joint="gripper_slave_joint" has_pid="false" multiplier="-1.0" max_effort="100.0" />
    <!-- <xacro:transmission_block joint_name="gripper_slave_joint" /> -->
    <gazebo reference="gripper_slave_joint">
      <provideFeedback>0</provideFeedback>
    </gazebo>


    <joint name="rod_left_joint" type="revolute">
      <origin xyz="0 0.0124 0.054" rpy="${0.32} 0 0" />
      <parent link="gripper_base_link" />
      <child link="rod_link" />
      <axis xyz="-1 0 0" />
      <limit lower="-3.31" upper="3.31" effort="100" velocity="4.50" />
      <dynamics damping="50" friction="1" />
      <mimic joint="gripper_joint" multiplier="1.26" offset="0" />
    </joint>
    <!-- mimic_joint_plugin has to be installed: -->
    <xacro:mimic_joint_plugin_gazebo name_prefix="rod_left_joint" following_joint="gripper_joint" mimic_joint="rod_left_joint" has_pid="false" multiplier="1.26" max_effort="100.0" />
    <!-- <xacro:transmission_block joint_name="rod_left_joint" /> -->
    <gazebo reference="rod_left_joint">
      <provideFeedback>0</provideFeedback>
    </gazebo>

    <joint name="rod_right_joint" type="revolute">
      <origin xyz="0 -0.0115 0.054" rpy="-${0.32} 0 0" />
      <parent link="gripper_base_link" />
      <child link="rod_slave_link" />
      <axis xyz="-1 0 0" />
      <limit lower="-3.31" upper="3.31" effort="100" velocity="4.50" />
      <dynamics damping="50" friction="1" />
      <mimic joint="gripper_joint" multiplier="-1.26" offset="0" />
    </joint>
    <!-- mimic_joint_plugin has to be installed: -->
    <xacro:mimic_joint_plugin_gazebo name_prefix="rod_right_joint" following_joint="gripper_joint" mimic_joint="rod_right_joint" has_pid="false" multiplier="-1.26" max_effort="100.0" />
    <!-- <xacro:transmission_block joint_name="rod_right_joint" /> -->
    <gazebo reference="rod_right_joint">
      <provideFeedback>0</provideFeedback>
    </gazebo>


    <joint name="tip_left_joint" type="revolute">
      <origin xyz="-0.007 0.052 0" rpy="-${0.02} 0 0" />
      <parent link="driving_gear_link" />
      <child link="gripper_tip_link" />
      <axis xyz="1 0 0" />
      <limit lower="-3.31" upper="3.31" effort="100" velocity="4.50" />
      <dynamics damping="50" friction="1" />
      <mimic joint="gripper_joint" multiplier="-0.8" offset="0" />
    </joint>
    <!-- mimic_joint_plugin has to be installed: -->
    <xacro:mimic_joint_plugin_gazebo name_prefix="tip_left_joint" following_joint="gripper_joint" mimic_joint="tip_left_joint" has_pid="false" multiplier="-0.8" max_effort="100.0" />
    <!-- <xacro:transmission_block joint_name="tip_left_joint" /> -->
    <gazebo reference="tip_left_joint">
      <provideFeedback>0</provideFeedback>
    </gazebo>

    <joint name="tip_right_joint" type="revolute">
      <origin xyz="-0.007 -0.052 0" rpy="${0.02} 0 0" />
      <parent link="slave_gear_link" />
      <child link="tip_slave_link" />
      <axis xyz="1 0 0" />
      <limit lower="-3.31" upper="3.31" effort="100" velocity="4.50" />
      <dynamics damping="50" friction="1" />
      <mimic joint="gripper_joint" multiplier="0.8" offset="0" />
    </joint>
    <!-- mimic_joint_plugin has to be installed: -->
    <xacro:mimic_joint_plugin_gazebo name_prefix="tip_right_joint" following_joint="gripper_joint" mimic_joint="tip_right_joint" has_pid="false" multiplier="0.8" max_effort="100.0" />
    <!-- <xacro:transmission_block joint_name="tip_right_joint" /> -->
    <gazebo reference="tip_right_joint">
      <provideFeedback>0</provideFeedback>
    </gazebo>

    <!-- ros_control plugin -->
    <gazebo>
      <plugin name="gazebo_ros_control" filename="libgazebo_ros_control.so">
        <robotNamespace>/</robotNamespace>
        <robotSimType>gazebo_ros_control/DefaultRobotHWSim</robotSimType>
        <legacyModeNS>true</legacyModeNS>
      </plugin>
    </gazebo>

  </xacro:macro>
</robot>
