<?xml version="1.0" encoding="utf-8"?>
<!-- =================================================================================== -->
<!-- |    This document was autogenerated by xacro from fenrir.xacro                   | -->
<!-- |    EDITING THIS FILE BY HAND IS NOT RECOMMENDED                                 | -->
<!-- =================================================================================== -->
<robot name="Fenrir">
  <!-- LINKS: main serial links -->
  <!-- Base link -->
  <link name="base_link">
    <visual>
      <origin rpy="0 0 0" xyz="0 0 0"/>
      <geometry>
        <mesh filename="package://fenrir/meshes/visual/base_link.stl" scale="0.01 0.01 0.01"/>
      </geometry>
      <material name="">
        <color rgba="0.117647058824 0.117647058824 0.117647058824 1.0"/>
      </material>
    </visual>
    <collision>
      <origin rpy="0 0 0" xyz="0 0 0"/>
      <geometry>
        <mesh filename="package://fenrir/meshes/collision/base_link.stl" scale="0.01 0.01 0.01"/>
      </geometry>
    </collision>
  </link>
  <link name="disk">
    <visual>
      <origin rpy="0 0 0" xyz="0 0 0"/>
      <geometry>
        <mesh filename="package://fenrir/meshes/visual/disk.stl" scale="0.01 0.01 0.01"/>
      </geometry>
      <material name="">
        <color rgba="0.117647058824 0.117647058824 0.117647058824 1.0"/>
      </material>
    </visual>
    <collision>
      <origin rpy="0 0 0" xyz="0 0 0"/>
      <geometry>
        <mesh filename="package://fenrir/meshes/collision/disk.stl" scale="0.01 0.01 0.01"/>
      </geometry>
    </collision>
  </link>
  <!-- Lower arm -->
  <link name="lower_arm">
    <visual>
      <origin rpy="0 0 0" xyz="0 0.022 0"/>
      <geometry>
        <mesh filename="package://fenrir/meshes/visual/lower_arm.stl" scale="0.01 0.01 0.01"/>
      </geometry>
      <material name="">
        <color rgba="0.117647058824 0.117647058824 0.117647058824 1.0"/>
      </material>
    </visual>
    <collision>
      <origin rpy="0 0 0" xyz="0 0.022 0"/>
      <geometry>
        <mesh filename="package://fenrir/meshes/collision/lower_arm.stl" scale="0.01 0.01 0.01"/>
      </geometry>
    </collision>
  </link>
  <!-- Fore arm -->
  <link name="forearm">
    <visual>
      <origin rpy="0 0 0" xyz="0 0 0"/>
      <geometry>
        <mesh filename="package://fenrir/meshes/visual/forearm.stl" scale="0.01 0.01 0.01"/>
      </geometry>
      <material name="">
        <color rgba="0.917647058824 0.356862745098 0.078431372549 1.0"/>
      </material>
    </visual>
    <visual>
      <origin rpy="0 0 0" xyz="0.0004 0.031 0.001"/>
      <geometry>
        <mesh filename="package://fenrir/meshes/visual/emblem.stl" scale="0.01 0.01 0.01"/>
      </geometry>
      <material name="">
        <color rgba="0.117647058824 0.117647058824 0.117647058824 1.0"/>
      </material>
    </visual>
    <visual>
      <origin rpy="-1.57079632679 -0.080 -3.14159265359" xyz="-0.0003 0.034 0.0051"/>
      <geometry>
        <mesh filename="package://fenrir/meshes/visual/wolf.stl" scale="0.01 0.01 0.01"/>
      </geometry>
      <material name="">
        <color rgba="0.917647058824 0.356862745098 0.078431372549 1.0"/>
      </material>
    </visual>
    <visual>
      <origin rpy="0 -1.57079632679 0" xyz="0.001 -0.0155 0.172"/>
      <geometry>
        <mesh filename="package://fenrir/meshes/visual/ax-12.stl" scale="0.01 0.01 0.01"/>
      </geometry>
      <material name="">
        <color rgba="0.117647058824 0.117647058824 0.117647058824 1.0"/>
      </material>
    </visual>
    <collision>
      <origin rpy="0 0 0" xyz="0 0 0"/>
      <geometry>
        <mesh filename="package://fenrir/meshes/collision/forearm.stl" scale="0.01 0.01 0.01"/>
      </geometry>
    </collision>
  </link>
  <!-- Gripper -->
  <link name="gripper_base">
    <visual>
      <origin rpy="0 -1.57079632679 0" xyz="0 0.001 0"/>
      <geometry>
        <mesh filename="package://fenrir/meshes/visual/ManipulatorServoHolder.stl" scale="0.01 0.01 0.01"/>
      </geometry>
      <material name="">
        <color rgba="0.117647058824 0.117647058824 0.117647058824 1.0"/>
      </material>
    </visual>
    <visual>
      <origin rpy="-3.14159265359 0 -3.14159265359" xyz="0.0315 -0.002 0.027"/>
      <geometry>
        <mesh filename="package://fenrir/meshes/visual/ax-12.stl" scale="0.01 0.01 0.01"/>
      </geometry>
      <material name="">
        <color rgba="0.117647058824 0.117647058824 0.117647058824 1.0"/>
      </material>
    </visual>
    <collision>
      <origin rpy="0 -1.57079632679 0" xyz="0 0.001 0"/>
      <geometry>
        <mesh filename="package://fenrir/meshes/collision/ManipulatorServoHolder.stl" scale="0.01 0.01 0.01"/>
      </geometry>
    </collision>
  </link>
  <link name="driving_gear">
    <visual>
      <origin rpy="0 -1.57079632679 0" xyz="0.0115 0 0"/>
      <geometry>
        <mesh filename="package://fenrir/meshes/visual/driving_gear.stl" scale="0.01 0.01 0.01"/>
      </geometry>
      <material name="">
        <color rgba="0.917647058824 0.356862745098 0.078431372549 1.0"/>
      </material>
    </visual>
    <collision>
      <origin rpy="0 -1.57079632679 0" xyz="0.0115 0 0"/>
      <geometry>
        <mesh filename="package://fenrir/meshes/collision/driving_gear.stl" scale="0.01 0.01 0.01"/>
      </geometry>
    </collision>
  </link>
  <link name="slave_gear">
    <visual>
      <origin rpy="0 -1.57079632679 0" xyz="0.005 0 0"/>
      <geometry>
        <mesh filename="package://fenrir/meshes/visual/slave_gear.stl" scale="0.01 0.01 0.01"/>
      </geometry>
      <material name="">
        <color rgba="0.917647058824 0.356862745098 0.078431372549 1.0"/>
      </material>
    </visual>
    <collision>
      <origin rpy="0 -1.57079632679 0" xyz="0.005 0 0"/>
      <geometry>
        <mesh filename="package://fenrir/meshes/collision/slave_gear.stl" scale="0.01 0.01 0.01"/>
      </geometry>
    </collision>
  </link>
  <link name="rod">
    <visual>
      <origin rpy="1.57079632679 0 1.57079632679" xyz="-0.0035 0 0"/>
      <geometry>
        <mesh filename="package://fenrir/meshes/visual/secondaryRod.stl" scale="0.01 0.01 0.01"/>
      </geometry>
      <material name="">
        <color rgba="0.917647058824 0.356862745098 0.078431372549 1.0"/>
      </material>
    </visual>
    <collision>
      <origin rpy="1.57079632679 0 1.57079632679" xyz="-0.0035 0 0"/>
      <geometry>
        <mesh filename="package://fenrir/meshes/collision/secondaryRod.stl" scale="0.01 0.01 0.01"/>
      </geometry>
    </collision>
  </link>
  <link name="rod_slave">
    <visual>
      <origin rpy="1.57079632679 0 -1.57079632679" xyz="0.0035 0 0"/>
      <geometry>
        <mesh filename="package://fenrir/meshes/visual/secondaryRod.stl" scale="0.01 0.01 0.01"/>
      </geometry>
      <material name="">
        <color rgba="0.917647058824 0.356862745098 0.078431372549 1.0"/>
      </material>
    </visual>
    <collision>
      <origin rpy="1.57079632679 0 -1.57079632679" xyz="0.0035 0 0"/>
      <geometry>
        <mesh filename="package://fenrir/meshes/collision/secondaryRod.stl" scale="0.01 0.01 0.01"/>
      </geometry>
    </collision>
  </link>
  <link name="gripper_tip">
    <visual>
      <origin rpy="0 -1.57079632679 0" xyz="0.0092 0 0"/>
      <geometry>
        <mesh filename="package://fenrir/meshes/visual/gripperTip.stl" scale="0.01 0.01 0.01"/>
      </geometry>
      <material name="">
        <color rgba="0.917647058824 0.356862745098 0.078431372549 1.0"/>
      </material>
    </visual>
    <collision>
      <origin rpy="0 -1.57079632679 0" xyz="0.0092 0 0"/>
      <geometry>
        <mesh filename="package://fenrir/meshes/collision/gripperTip.stl" scale="0.01 0.01 0.01"/>
      </geometry>
    </collision>
  </link>
  <link name="tip_slave">
    <visual>
      <origin rpy="3.14159265359 -1.57079632679 0" xyz="-0.0092 0 0"/>
      <geometry>
        <mesh filename="package://fenrir/meshes/visual/gripperTip.stl" scale="0.01 0.01 0.01"/>
      </geometry>
      <material name="">
        <color rgba="0.917647058824 0.356862745098 0.078431372549 1.0"/>
      </material>
    </visual>
    <collision>
      <origin rpy="3.14159265359 -1.57079632679 0" xyz="-0.0092 0 0"/>
      <geometry>
        <mesh filename="package://fenrir/meshes/collision/gripperTip.stl" scale="0.01 0.01 0.01"/>
      </geometry>
    </collision>
  </link>
  <!-- JOINTS: main serial chain -->
  <joint name="Base" type="revolute">
    <origin rpy="0 0 0" xyz="0 0 0.080"/>
    <parent link="base_link"/>
    <child link="disk"/>
    <axis xyz="0 0 1"/>
    <limit effort="0" lower="-2.967" upper="2.967" velocity="4.01"/>
  </joint>
  <joint name="Shoulder" type="revolute">
    <origin rpy="0 -0.6 0" xyz="0 -0.001 0.089"/>
    <parent link="disk"/>
    <child link="lower_arm"/>
    <axis xyz="0 1 0"/>
    <limit effort="0" lower="-3.57" upper="3.79" velocity="3.93"/>
  </joint>
  <joint name="Elbow" type="revolute">
    <origin rpy="0 2.4 0" xyz="0 0.001 0.195"/>
    <parent link="lower_arm"/>
    <child link="forearm"/>
    <axis xyz="0 -1 0"/>
    <limit effort="0" lower="-6.14" upper="6.66" velocity="4.01"/>
  </joint>
  <joint name="Wrist" type="revolute">
    <origin rpy="0 0 0" xyz="0 0 0.19"/>
    <parent link="forearm"/>
    <child link="gripper_base"/>
    <axis xyz="0 0 -1"/>
    <limit effort="0" lower="-3.31" upper="3.31" velocity="7.50"/>
  </joint>
  <joint name="Gripper" type="revolute">
    <origin rpy="0.40 0 0" xyz="0 0.014 0.0262"/>
    <parent link="gripper_base"/>
    <child link="driving_gear"/>
    <axis xyz="-1 0 0"/>
    <limit effort="0" lower="-3.31" upper="3.31" velocity="7.50"/>
  </joint>
  <joint name="Gripper_slave" type="revolute">
    <origin rpy="-0.40 0 0" xyz="0 -0.0135 0.0262"/>
    <parent link="gripper_base"/>
    <child link="slave_gear"/>
    <axis xyz="-1 0 0"/>
    <limit effort="0" lower="-3.31" upper="3.31" velocity="7.50"/>
    <mimic joint="Gripper" multiplier="-1" offset="0"/>
  </joint>
  <joint name="Rod_left" type="revolute">
    <origin rpy="0.40 0 0" xyz="0 0.0124 0.054"/>
    <parent link="gripper_base"/>
    <child link="rod"/>
    <axis xyz="-1 0 0"/>
    <limit effort="0" lower="-3.31" upper="3.31" velocity="7.50"/>
    <mimic joint="Gripper" multiplier="1.26" offset="0"/>
  </joint>
  <joint name="Rod_right" type="revolute">
    <origin rpy="-0.40 0 0" xyz="0 -0.0115 0.054"/>
    <parent link="gripper_base"/>
    <child link="rod_slave"/>
    <axis xyz="-1 0 0"/>
    <limit effort="0" lower="-3.31" upper="3.31" velocity="7.50"/>
    <mimic joint="Gripper" multiplier="-1.26" offset="0"/>
  </joint>
  <joint name="Tip_left" type="revolute">
    <origin rpy="-0.07 0 0" xyz="0 0.052 0"/>
    <parent link="driving_gear"/>
    <child link="gripper_tip"/>
    <axis xyz="-1 0 0"/>
    <limit effort="0" lower="-3.31" upper="3.31" velocity="7.50"/>
    <mimic joint="Gripper" multiplier="-0.8" offset="0"/>
  </joint>
  <joint name="Tip_right" type="revolute">
    <origin rpy="0.07 0 0" xyz="0 -0.052 0"/>
    <parent link="slave_gear"/>
    <child link="tip_slave"/>
    <axis xyz="-1 0 0"/>
    <limit effort="0" lower="-3.31" upper="3.31" velocity="7.50"/>
    <mimic joint="Gripper" multiplier="0.8" offset="0"/>
  </joint>
</robot>

