<?xml version="1.0" encoding="utf-8"?>
<!-- =================================================================================== -->
<!-- |    This document was autogenerated by xacro from fenrir.xacro                   | -->
<!-- |    EDITING THIS FILE BY HAND IS NOT RECOMMENDED                                 | -->
<!-- =================================================================================== -->
<robot name="Fenrir">
  <link name="base_link">
    <visual>
      <origin rpy="0 0 0" xyz="0 0 0"/>
      <geometry>
        <mesh filename="package://fenrir/meshes/visual/base_link.stl" scale="0.01 0.01 0.01"/>
      </geometry>
      <material name="">
        <color rgba="0.117647058824 0.117647058824 0.117647058824 1.0"/>
      </material>
    </visual>
    <collision>
      <origin rpy="0 0 0" xyz="0 0 0"/>
      <geometry>
        <mesh filename="package://fenrir/meshes/collision/base_link.stl" scale="0.01 0.01 0.01"/>
      </geometry>
    </collision>
  </link>
  <link name="disk">
    <visual>
      <origin rpy="0 0 0" xyz="0 0 0"/>
      <geometry>
        <mesh filename="package://fenrir/meshes/visual/disk.stl" scale="0.01 0.01 0.01"/>
      </geometry>
      <material name="">
        <color rgba="0.117647058824 0.117647058824 0.117647058824 1.0"/>
      </material>
    </visual>
    <collision>
      <origin rpy="0 0 0" xyz="0 0 0"/>
      <geometry>
        <mesh filename="package://fenrir/meshes/collision/disk.stl" scale="0.01 0.01 0.01"/>
      </geometry>
    </collision>
  </link>
  <link name="lower_arm">
    <visual>
      <origin rpy="0 0 0" xyz="0 0.022 0"/>
      <geometry>
        <mesh filename="package://fenrir/meshes/visual/lower_arm.stl" scale="0.01 0.01 0.01"/>
      </geometry>
      <material name="">
        <color rgba="0.117647058824 0.117647058824 0.117647058824 1.0"/>
      </material>
    </visual>
    <collision>
      <origin rpy="0 0 0" xyz="0 0 0"/>
      <geometry>
        <mesh filename="package://fenrir/meshes/collision/lower_arm.stl" scale="0.01 0.01 0.01"/>
      </geometry>
    </collision>
  </link>
  <link name="forearm">
    <visual>
      <origin rpy="0 0 0" xyz="0 0 0"/>
      <geometry>
        <mesh filename="package://fenrir/meshes/visual/forearm.stl" scale="0.01 0.01 0.01"/>
      </geometry>
      <material name="">
        <color rgba="0.917647058824 0.356862745098 0.078431372549 1.0"/>
      </material>
    </visual>
    <collision>
      <origin rpy="0 0 0" xyz="0 0 0"/>
      <geometry>
        <mesh filename="package://fenrir/meshes/collision/forearm.stl" scale="0.01 0.01 0.01"/>
      </geometry>
    </collision>
  </link>
  <link name="end_effector">
    <visual>
      <origin rpy="0 0 0" xyz="0 0 0"/>
      <geometry>
        <mesh filename="package://fenrir/meshes/visual/end_effector.stl" scale="0.01 0.01 0.01"/>
      </geometry>
      <material name="">
        <color rgba="0.117647058824 0.117647058824 0.117647058824 1.0"/>
      </material>
    </visual>
    <collision>
      <origin rpy="0 0 0" xyz="0 0 0"/>
      <geometry>
        <mesh filename="package://fenrir/meshes/collision/end_effector.stl" scale="0.01 0.01 0.01"/>
      </geometry>
    </collision>
  </link>
  <!-- joints: main serial chain -->
  <joint name="Base" type="revolute">
    <origin rpy="0 0 0" xyz="0 0 0.080"/>
    <parent link="base_link"/>
    <child link="disk"/>
    <axis xyz="0 0 1"/>
    <limit effort="0" lower="-2.967" upper="2.967" velocity="4.01"/>
  </joint>
  <joint name="Shoulder" type="revolute">
    <origin rpy="0 0 0" xyz="0 0 0.080"/>
    <parent link="disk"/>
    <child link="lower_arm"/>
    <axis xyz="0 1 0"/>
    <limit effort="0" lower="-1.57" upper="2.79" velocity="3.93"/>
  </joint>
  <joint name="Elbow" type="revolute">
    <origin rpy="0 0 0" xyz="0 0.001 0.195"/>
    <parent link="lower_arm"/>
    <child link="forearm"/>
    <axis xyz="0 -1 0"/>
    <limit effort="0" lower="-3.14" upper="4.66" velocity="4.01"/>
  </joint>
  <joint name="Wrist" type="revolute">
    <origin rpy="0 0 0" xyz="0 0 0.15"/>
    <parent link="forearm"/>
    <child link="end_effector"/>
    <axis xyz="-1 0 0"/>
    <limit effort="0" lower="-3.31" upper="3.31" velocity="7.50"/>
  </joint>
</robot>
